Workbook

Sheet Pipeline_Control
A1: Pipeline Row | B1: Deal ID | C1: Product / Project | D1: Customer | E1: Category | F1: Quarter | G1: Sales Rep | H1: Deal Status | I1: Include in Forecast | J1: Expected Close Date | K1: Pipeline Amount | L1: Probability | M1: Weighted Forecast | N1: Approved SO Number(s) | O1: Approved SO Amount | P1: SO Approved Date | Q1: Remaining Pipeline After SO | R1: SO Conversion % | S1: Forecast Status | T1: Stale Deal Flag | U1: Notes | V1: Dashboard Notes | W1: Data Quality Check | X1: Expected Ship/Invoice Date | Y1: Expected Cash Date | Z1: Deposit % | AA1: Deposit Cash Date | AB1: Balance Cash Date | AC1: SO Match Status | AD1: Converted Amount | AE1: Remaining Forecast Amount | AF1: Timing Confidence | AG1: Last Reviewed Date | AH1: Manual Override Reason | AI1: Pipeline Visibility | AJ1: Cash Forecast Eligibility | AK1: Liquidity Feed Eligible | AL1: Mapped SO Amount | AM1: SO Mapping Review Required | AN1: Remaining Pipeline - Mapping Safe | AO1: Eligibility Reason | AP1: Cash Timing Bucket | AQ1: App Control Notes
A2: 2 | B2: DPS-0002 | C2: SDJ GEN Z BAGS | D2: SDJ | E2: SOFT GOODS | F2: Q4 | G2: Danny Park | H2: Won | I2: Y | J2: 2026-04-30 | K2: 3000000 | L2: 1 | M2: 3000000 | N2: SO2599, SO2597, SO2598, 2608, 2609, 2610, 2611, 2612, 2613 | O2: 2672706 | P2: 2026-04-30 | Q2: 327294 | R2: 89.1% | S2: Partially Converted | U2: based on invoice date | W2: OK | X2: 2026-04-30 | Y2: 2026-05-30 | Z2: 0 | AB2: 2026-05-30 | AC2: SO Linked | AD2: 2672706 | AE2: 327294 | AF2: High - SO Supported | AG2: 2026-05-23 | AI2: =IF(OR($H2="Lost",$H2="Dead"),"Lost",IF($I2<>"Y","Excluded",IF($N2<>"","Converted/Partially Converted",IF($J2="","Watchlist","Active")))) -> Converted/Partially Converted | AJ2: =IF($I2<>"Y","Not Eligible - Excluded",IF(OR($H2="Lost",$H2="Dead"),"Not Eligible - Lost",IF($J2="","Scenario Only - No Close Date",IF($X2="","Scenario Only - No Ship Date",IF($Y2="","Scenario Only - No Cash Date",IF($AM2="Y","Not Eligible - SO Mapping Review","Eligible")))))) -> Not Eligible - SO Mapping Review | AK2: =IF($AJ2="Eligible","Y","N") -> N | AL2: =SUMIFS(SO_Mapping!$F:$F,SO_Mapping!$A:$A,$B2) -> 0 | AM2: =IF(AND($N2<>"",$AL2=0),"Y",IF(ABS($O2-$AL2)>1,"Y","N")) -> Y | AN2: =MAX(0,$K2-$AL2) -> 3000000 | AO2: =IF($AK2="Y","Cash eligible",IF($I2<>"Y","Excluded by control flag",IF($J2="","No expected close date",IF($X2="","No ship/invoice timing",IF($Y2="","No cash timing",IF($AM2="Y","SO mapping must be resolved","Review required")))))) -> SO mapping must be resolved | AP2: =IF($AK2="Y",TEXT($Y2,"yyyy-mm-dd"),"")
A3: 4 | B3: DPS-0004 | C3: SDJ JET BAGS | D3: SDJ | E3: SOFT GOODS | F3: Q3 | G3: Danny Park | H3: Won | I3: Y | J3: 2026-05-06 | K3: 1560000 | L3: 0.75 | M3: 1170000 | N3: SO2601, SO2602 | O3: 290080 | P3: 2026-05-06 | Q3: 1269920 | R3: 18.6% | S3: Partially Converted | U3: based on invoice date | W3: OK | X3: 2026-05-06 | Y3: 2026-06-05 | Z3: 0 | AB3: 2026-06-05 | AC3: SO Linked | AD3: 290080 | AE3: 1269920 | AF3: High - SO Supported | AG3: 2026-05-23 | AI3: =IF(OR($H3="Lost",$H3="Dead"),"Lost",IF($I3<>"Y","Excluded",IF($N3<>"","Converted/Partially Converted",IF($J3="","Watchlist","Active")))) -> Converted/Partially Converted | AJ3: =IF($I3<>"Y","Not Eligible - Excluded",IF(OR($H3="Lost",$H3="Dead"),"Not Eligible - Lost",IF($J3="","Scenario Only - No Close Date",IF($X3="","Scenario Only - No Ship Date",IF($Y3="","Scenario Only - No Cash Date",IF($AM3="Y","Not Eligible - SO Mapping Review","Eligible")))))) -> Not Eligible - SO Mapping Review | AK3: =IF($AJ3="Eligible","Y","N") -> N | AL3: =SUMIFS(SO_Mapping!$F:$F,SO_Mapping!$A:$A,$B3) -> 0 | AM3: =IF(AND($N3<>"",$AL3=0),"Y",IF(ABS($O3-$AL3)>1,"Y","N")) -> Y | AN3: =MAX(0,$K3-$AL3) -> 1560000 | AO3: =IF($AK3="Y","Cash eligible",IF($I3<>"Y","Excluded by control flag",IF($J3="","No expected close date",IF($X3="","No ship/invoice timing",IF($Y3="","No cash timing",IF($AM3="Y","SO mapping must be resolved","Review required")))))) -> SO mapping must be resolved | AP3: =IF($AK3="Y",TEXT($Y3,"yyyy-mm-dd"),"")
A4: 5 | B4: DPS-0005 | C4: SDJ GEN Z BAGS | D4: SDJ | E4: SOFT GOODS | F4: Q2 | G4: Danny Park | H4: Won | I4: Y | J4: 2026-02-25 | K4: 1500000 | L4: 0.75 | M4: 1125000 | N4: open: SO2563, 2564, 2562, invoiced: 2561 | O4: 1114750 | P4: 2026-02-25 | Q4: 385250 | R4: 74.3% | S4: Partially Converted | U4: 2561 is still open, based on invoice date | W4: OK | X4: 2026-02-25 | Y4: 2026-03-27 | Z4: 0 | AB4: 2026-03-27 | AC4: SO Linked | AD4: 1114750 | AE4: 385250 | AF4: High - SO Supported | AG4: 2026-05-23 | AI4: =IF(OR($H4="Lost",$H4="Dead"),"Lost",IF($I4<>"Y","Excluded",IF($N4<>"","Converted/Partially Converted",IF($J4="","Watchlist","Active")))) -> Converted/Partially Converted | AJ4: =IF($I4<>"Y","Not Eligible - Excluded",IF(OR($H4="Lost",$H4="Dead"),"Not Eligible - Lost",IF($J4="","Scenario Only - No Close Date",IF($X4="","Scenario Only - No Ship Date",IF($Y4="","Scenario Only - No Cash Date",IF($AM4="Y","Not Eligible - SO Mapping Review","Eligible")))))) -> Not Eligible - SO Mapping Review | AK4: =IF($AJ4="Eligible","Y","N") -> N | AL4: =SUMIFS(SO_Mapping!$F:$F,SO_Mapping!$A:$A,$B4) -> 0 | AM4: =IF(AND($N4<>"",$AL4=0),"Y",IF(ABS($O4-$AL4)>1,"Y","N")) -> Y | AN4: =MAX(0,$K4-$AL4) -> 1500000 | AO4: =IF($AK4="Y","Cash eligible",IF($I4<>"Y","Excluded by control flag",IF($J4="","No expected close date",IF($X4="","No ship/invoice timing",IF($Y4="","No cash timing",IF($AM4="Y","SO mapping must be resolved","Review required")))))) -> SO mapping must be resolved | AP4: =IF($AK4="Y",TEXT($Y4,"yyyy-mm-dd"),"")
A5: 6 | B5: DPS-0006 | C5: SDJ JET BAGS | D5: SDJ | E5: SOFT GOODS | F5: Q2 | G5: Danny Park | H5: Won | I5: Y | J5: 2026-01-15 | K5: 1150000 | L5: 0.75 | M5: 862500 | N5: SO2531, 2532 | O5: 259000 | P5: 2026-01-15 | Q5: 891000 | R5: 22.5% | S5: Partially Converted | U5: based on invoice date | W5: OK | X5: 2026-01-15 | Y5: 2026-02-14 | Z5: 0 | AB5: 2026-02-14 | AC5: SO Linked | AD5: 259000 | AE5: 891000 | AF5: High - SO Supported | AG5: 2026-05-23 | AI5: =IF(OR($H5="Lost",$H5="Dead"),"Lost",IF($I5<>"Y","Excluded",IF($N5<>"","Converted/Partially Converted",IF($J5="","Watchlist","Active")))) -> Converted/Partially Converted | AJ5: =IF($I5<>"Y","Not Eligible - Excluded",IF(OR($H5="Lost",$H5="Dead"),"Not Eligible - Lost",IF($J5="","Scenario Only - No Close Date",IF($X5="","Scenario Only - No Ship Date",IF($Y5="","Scenario Only - No Cash Date",IF($AM5="Y","Not Eligible - SO Mapping Review","Eligible")))))) -> Not Eligible - SO Mapping Review | AK5: =IF($AJ5="Eligible","Y","N") -> N | AL5: =SUMIFS(SO_Mapping!$F:$F,SO_Mapping!$A:$A,$B5) -> 0 | AM5: =IF(AND($N5<>"",$AL5=0),"Y",IF(ABS($O5-$AL5)>1,"Y","N")) -> Y | AN5: =MAX(0,$K5-$AL5) -> 1150000 | AO5: =IF($AK5="Y","Cash eligible",IF($I5<>"Y","Excluded by control flag",IF($J5="","No expected close date",IF($X5="","No ship/invoice timing",IF($Y5="","No cash timing",IF($AM5="Y","SO mapping must be resolved","Review required")))))) -> SO mapping must be resolved | AP5: =IF($AK5="Y",TEXT($Y5,"yyyy-mm-dd"),"")
A6: 7 | B6: DPS-0007 | C6: SDJ JET BAGS | D6: SDJ | E6: SOFT GOODS | F6: Q4 | G6: Danny Park | H6: Open | I6: Y | K6: 1100000 | L6: 0.75 | M6: 825000 | Q6: 1100000 | R6: 0.0% | S6: Open | W6: OK | Z6: 0 | AC6: No SO Yet | AD6: 0 | AE6: 1100000 | AF6: Low - Missing Timing | AG6: 2026-05-23 | AI6: =IF(OR($H6="Lost",$H6="Dead"),"Lost",IF($I6<>"Y","Excluded",IF($N6<>"","Converted/Partially Converted",IF($J6="","Watchlist","Active")))) -> Watchlist | AJ6: =IF($I6<>"Y","Not Eligible - Excluded",IF(OR($H6="Lost",$H6="Dead"),"Not Eligible - Lost",IF($J6="","Scenario Only - No Close Date",IF($X6="","Scenario Only - No Ship Date",IF($Y6="","Scenario Only - No Cash Date",IF($AM6="Y","Not Eligible - SO Mapping Review","Eligible")))))) -> Scenario Only - No Close Date | AK6: =IF($AJ6="Eligible","Y","N") -> N | AL6: =SUMIFS(SO_Mapping!$F:$F,SO_Mapping!$A:$A,$B6) -> 0 | AM6: =IF(AND($N6<>"",$AL6=0),"Y",IF(ABS($O6-$AL6)>1,"Y","N")) -> N | AN6: =MAX(0,$K6-$AL6) -> 1100000 | AO6: =IF($AK6="Y","Cash eligible",IF($I6<>"Y","Excluded by control flag",IF($J6="","No expected close date",IF($X6="","No ship/invoice timing",IF($Y6="","No cash timing",IF($AM6="Y","SO mapping must be resolved","Review required")))))) -> No expected close date | AP6: =IF($AK6="Y",TEXT($Y6,"yyyy-mm-dd"),"")
A7: 9 | B7: DPS-0009 | C7: GEN Z - Spring bag | D7: SDJ | E7: SOFT GOODS | F7: Q3 | G7: Danny Park | H7: Open | I7: Y | K7: 500000 | L7: 0.9 | M7: 450000 | Q7: 500000 | R7: 0.0% | S7: Open | W7: OK | Z7: 0 | AC7: No SO Yet | AD7: 0 | AE7: 500000 | AF7: Low - Missing Timing | AG7: 2026-05-23 | AI7: =IF(OR($H7="Lost",$H7="Dead"),"Lost",IF($I7<>"Y","Excluded",IF($N7<>"","Converted/Partially Converted",IF($J7="","Watchlist","Active")))) -> Watchlist | AJ7: =IF($I7<>"Y","Not Eligible - Excluded",IF(OR($H7="Lost",$H7="Dead"),"Not Eligible - Lost",IF($J7="","Scenario Only - No Close Date",IF($X7="","Scenario Only - No Ship Date",IF($Y7="","Scenario Only - No Cash Date",IF($AM7="Y","Not Eligible - SO Mapping Review","Eligible")))))) -> Scenario Only - No Close Date | AK7: =IF($AJ7="Eligible","Y","N") -> N | AL7: =SUMIFS(SO_Mapping!$F:$F,SO_Mapping!$A:$A,$B7) -> 0 | AM7: =IF(AND($N7<>"",$AL7=0),"Y",IF(ABS($O7-$AL7)>1,"Y","N")) -> N | AN7: =MAX(0,$K7-$AL7) -> 500000 | AO7: =IF($AK7="Y","Cash eligible",IF($I7<>"Y","Excluded by control flag",IF($J7="","No expected close date",IF($X7="","No ship/invoice timing",IF($Y7="","No cash timing",IF($AM7="Y","SO mapping must be resolved","Review required")))))) -> No expected close date | AP7: =IF($AK7="Y",TEXT($Y7,"yyyy-mm-dd"),"")
A8: 11 | B8: DPS-0011 | C8: SDJ JET BAGS | D8: SDJ | E8: SOFT GOODS | F8: Q2 | G8: Danny Park | H8: Won | I8: Y | J8: 2026-04-28 | K8: 500000 | L8: 0.75 | M8: 375000 | N8: SO2547, 2548, 2549; open: 2545, 2546, 2550, 2551, various | O8: 65518 | P8: 2026-04-28 | Q8: 434482 | R8: 13.1% | S8: Partially Converted | U8: CARDS ONLY - invoiced and open | W8: OK | X8: 2026-04-28 | Y8: 2026-05-28 | Z8: 0 | AB8: 2026-05-28 | AC8: SO Linked | AD8: 65518 | AE8: 434482 | AF8: High - SO Supported | AG8: 2026-05-23 | AI8: =IF(OR($H8="Lost",$H8="Dead"),"Lost",IF($I8<>"Y","Excluded",IF($N8<>"","Converted/Partially Converted",IF($J8="","Watchlist","Active")))) -> Converted/Partially Converted | AJ8: =IF($I8<>"Y","Not Eligible - Excluded",IF(OR($H8="Lost",$H8="Dead"),"Not Eligible - Lost",IF($J8="","Scenario Only - No Close Date",IF($X8="","Scenario Only - No Ship Date",IF($Y8="","Scenario Only - No Cash Date",IF($AM8="Y","Not Eligible - SO Mapping Review","Eligible")))))) -> Not Eligible - SO Mapping Review | AK8: =IF($AJ8="Eligible","Y","N") -> N | AL8: =SUMIFS(SO_Mapping!$F:$F,SO_Mapping!$A:$A,$B8) -> 0 | AM8: =IF(AND($N8<>"",$AL8=0),"Y",IF(ABS($O8-$AL8)>1,"Y","N")) -> Y | AN8: =MAX(0,$K8-$AL8) -> 500000 | AO8: =IF($AK8="Y","Cash eligible",IF($I8<>"Y","Excluded by control flag",IF($J8="","No expected close date",IF($X8="","No ship/invoice timing",IF($Y8="","No cash timing",IF($AM8="Y","SO mapping must be resolved","Review required")))))) -> SO mapping must be resolved | AP8: =IF($AK8="Y",TEXT($Y8,"yyyy-mm-dd"),"")
A9: 12 | B9: DPS-0012 | C9: Foundation Sample Packets | D9: TOWER 28 | E9: COPACKING | F9: Q2 | G9: Jackie King | H9: Won | I9: Y | J9: 2026-02-09 | K9: 275000 | L9: 1 | M9: 275000 | N9: SO2554 | O9: 280000 | P9: 2026-02-09 | R9: 101.8% | S9: Fully Converted | W9: OK | X9: 2026-02-09 | Y9: 2026-03-11 | Z9: 0 | AB9: 2026-03-11 | AC9: SO Linked | AD9: 280000 | AE9: 0 | AF9: High - SO Supported | AG9: 2026-05-23 | AI9: =IF(OR($H9="Lost",$H9="Dead"),"Lost",IF($I9<>"Y","Excluded",IF($N9<>"","Converted/Partially Converted",IF($J9="","Watchlist","Active")))) -> Converted/Partially Converted | AJ9: =IF($I9<>"Y","Not Eligible - Excluded",IF(OR($H9="Lost",$H9="Dead"),"Not Eligible - Lost",IF($J9="","Scenario Only - No Close Date",IF($X9="","Scenario Only - No Ship Date",IF($Y9="","Scenario Only - No Cash Date",IF($AM9="Y","Not Eligible - SO Mapping Review","Eligible")))))) -> Eligible | AK9: =IF($AJ9="Eligible","Y","N") -> Y | AL9: =SUMIFS(SO_Mapping!$F:$F,SO_Mapping!$A:$A,$B9) -> 280000 | AM9: =IF(AND($N9<>"",$AL9=0),"Y",IF(ABS($O9-$AL9)>1,"Y","N")) -> N | AN9: =MAX(0,$K9-$AL9) -> 0 | AO9: =IF($AK9="Y","Cash eligible",IF($I9<>"Y","Excluded by control flag",IF($J9="","No expected close date",IF($X9="","No ship/invoice timing",IF($Y9="","No cash timing",IF($AM9="Y","SO mapping must be resolved","Review required")))))) -> Cash eligible | AP9: =IF($AK9="Y",TEXT($Y9,"yyyy-mm-dd"),"") -> 2026-03-11
A10: 13 | B10: DPS-0013 | C10: RO - Replenishment | D10: RO | E10: PRIMARY | F10: Q1 | G10: Jing Santos | H10: Won | I10: Y | J10: 2026-01-08 | K10: 300000 | L10: 0.9 | M10: 270000 | N10: SO2528, SO2492, SO2508 | O10: 380572 | P10: 2026-01-08 | R10: 126.9% | S10: Fully Converted | W10: Review SO over pipeline | X10: 2026-01-08 | Y10: 2026-02-07 | Z10: 0 | AB10: 2026-02-07 | AC10: SO Linked | AD10: 380572 | AE10: 0 | AF10: Do Not Use - Data Issue | AG10: 2026-05-23 | AI10: =IF(OR($H10="Lost",$H10="Dead"),"Lost",IF($I10<>"Y","Excluded",IF($N10<>"","Converted/Partially Converted",IF($J10="","Watchlist","Active")))) -> Converted/Partially Converted | AJ10: =IF($I10<>"Y","Not Eligible - Excluded",IF(OR($H10="Lost",$H10="Dead"),"Not Eligible - Lost",IF($J10="","Scenario Only - No Close Date",IF($X10="","Scenario Only - No Ship Date",IF($Y10="","Scenario Only - No Cash Date",IF($AM10="Y","Not Eligible - SO Mapping Review","Eligible")))))) -> Not Eligible - SO Mapping Review | AK10: =IF($AJ10="Eligible","Y","N") -> N | AL10: =SUMIFS(SO_Mapping!$F:$F,SO_Mapping!$A:$A,$B10) -> 0 | AM10: =IF(AND($N10<>"",$AL10=0),"Y",IF(ABS($O10-$AL10)>1,"Y","N")) -> Y | AN10: =MAX(0,$K10-$AL10) -> 300000 | AO10: =IF($AK10="Y","Cash eligible",IF($I10<>"Y","Excluded by control flag",IF($J10="","No expected close date",IF($X10="","No ship/invoice timing",IF($Y10="","No cash timing",IF($AM10="Y","SO mapping must be resolved","Review required")))))) -> SO mapping must be resolved | AP10: =IF($AK10="Y",TEXT($Y10,"yyyy-mm-dd"),"")
A11: 14 | B11: DPS-0014 | C11: Pelvic Health (3 SKUs) | D11: HAVEN HEALTH | E11: TURNKEY | F11: Q3 | G11: Jackie King | H11: Open | I11: Y | K11: 340000 | L11: 0.75 | M11: 255000 | Q11: 340000 | R11: 0.0% | S11: Open | W11: OK | Z11: 0 | AC11: No SO Yet | AD11: 0 | AE11: 340000 | AF11: Low - Missing Timing | AG11: 2026-05-23 | AI11: =IF(OR($H11="Lost",$H11="Dead"),"Lost",IF($I11<>"Y","Excluded",IF($N11<>"","Converted/Partially Converted",IF($J11="","Watchlist","Active")))) -> Watchlist | AJ11: =IF($I11<>"Y","Not Eligible - Excluded",IF(OR($H11="Lost",$H11="Dead"),"Not Eligible - Lost",IF($J11="","Scenario Only - No Close Date",IF($X11="","Scenario Only - No Ship Date",IF($Y11="","Scenario Only - No Cash Date",IF($AM11="Y","Not Eligible - SO Mapping Review","Eligible")))))) -> Scenario Only - No Close Date | AK11: =IF($AJ11="Eligible","Y","N") -> N | AL11: =SUMIFS(SO_Mapping!$F:$F,SO_Mapping!$A:$A,$B11) -> 0 | AM11: =IF(AND($N11<>"",$AL11=0),"Y",IF(ABS($O11-$AL11)>1,"Y","N")) -> N | AN11: =MAX(0,$K11-$AL11) -> 340000 | AO11: =IF($AK11="Y","Cash eligible",IF($I11<>"Y","Excluded by control flag",IF($J11="","No expected close date",IF($X11="","No ship/invoice timing",IF($Y11="","No cash timing",IF($AM11="Y","SO mapping must be resolved","Review required")))))) -> No expected close date | AP11: =IF($AK11="Y",TEXT($Y11,"yyyy-mm-dd"),"")
A12: 15 | B12: DPS-0015 | C12: SDJ GEN Z BAGS | D12: SDJ | E12: SOFT GOODS | F12: Q4 | G12: Danny Park | H12: Open | I12: Y | K12: 300000 | L12: 0.8 | M12: 240000 | Q12: 300000 | R12: 0.0% | S12: Open | W12: OK | Z12: 0 | AC12: No SO Yet | AD12: 0 | AE12: 300000 | AF12: Low - Missing Timing | AG12: 2026-05-23 | AI12: =IF(OR($H12="Lost",$H12="Dead"),"Lost",IF($I12<>"Y","Excluded",IF($N12<>"","Converted/Partially Converted",IF($J12="","Watchlist","Active")))) -> Watchlist | AJ12: =IF($I12<>"Y","Not Eligible - Excluded",IF(OR($H12="Lost",$H12="Dead"),"Not Eligible - Lost",IF($J12="","Scenario Only - No Close Date",IF($X12="","Scenario Only - No Ship Date",IF($Y12="","Scenario Only - No Cash Date",IF($AM12="Y","Not Eligible - SO Mapping Review","Eligible")))))) -> Scenario Only - No Close Date | AK12: =IF($AJ12="Eligible","Y","N") -> N | AL12: =SUMIFS(SO_Mapping!$F:$F,SO_Mapping!$A:$A,$B12) -> 0 | AM12: =IF(AND($N12<>"",$AL12=0),"Y",IF(ABS($O12-$AL12)>1,"Y","N")) -> N | AN12: =MAX(0,$K12-$AL12) -> 300000 | AO12: =IF($AK12="Y","Cash eligible",IF($I12<>"Y","Excluded by control flag",IF($J12="","No expected close date",IF($X12="","No ship/invoice timing",IF($Y12="","No cash timing",IF($AM12="Y","SO mapping must be resolved","Review required")))))) -> No expected close date | AP12: =IF($AK12="Y",TEXT($Y12,"yyyy-mm-dd"),"")
A13: 16 | B13: DPS-0016 | C13: Pattern Hair Care Line | D13: PATTERN | E13: PRIMARY | F13: Q4 | G13: Jing Santos | H13: Open | I13: Y | K13: 300000 | L13: 0.75 | M13: 225000 | Q13: 300000 | R13: 0.0% | S13: Open | W13: OK | Z13: 0 | AC13: No SO Yet | AD13: 0 | AE13: 300000 | AF13: Low - Missing Timing | AG13: 2026-05-23 | AI13: =IF(OR($H13="Lost",$H13="Dead"),"Lost",IF($I13<>"Y","Excluded",IF($N13<>"","Converted/Partially Converted",IF($J13="","Watchlist","Active")))) -> Watchlist | AJ13: =IF($I13<>"Y","Not Eligible - Excluded",IF(OR($H13="Lost",$H13="Dead"),"Not Eligible - Lost",IF($J13="","Scenario Only - No Close Date",IF($X13="","Scenario Only - No Ship Date",IF($Y13="","Scenario Only - No Cash Date",IF($AM13="Y","Not Eligible - SO Mapping Review","Eligible")))))) -> Scenario Only - No Close Date | AK13: =IF($AJ13="Eligible","Y","N") -> N | AL13: =SUMIFS(SO_Mapping!$F:$F,SO_Mapping!$A:$A,$B13) -> 0 | AM13: =IF(AND($N13<>"",$AL13=0),"Y",IF(ABS($O13-$AL13)>1,"Y","N")) -> N | AN13: =MAX(0,$K13-$AL13) -> 300000 | AO13: =IF($AK13="Y","Cash eligible",IF($I13<>"Y","Excluded by control flag",IF($J13="","No expected close date",IF($X13="","No ship/invoice timing",IF($Y13="","No cash timing",IF($AM13="Y","SO mapping must be resolved","Review required")))))) -> No expected close date | AP13: =IF($AK13="Y",TEXT($Y13,"yyyy-mm-dd"),"")
A14: 17 | B14: DPS-0017 | C14: COLOGNE BOXES - Replenishment | D14: DRSQ | E14: SECONDARY | F14: Q4 | G14: Danny Park | H14: Won | I14: Y | J14: 2026-05-13 | K14: 241000 | L14: 0.75 | M14: 180750 | N14: SO2605 | O14: 104760 | P14: 2026-05-13 | Q14: 136240 | R14: 43.5% | S14: Partially Converted | W14: OK | X14: 2026-05-13 | Y14: 2026-06-12 | Z14: 0 | AB14: 2026-06-12 | AC14: SO Linked | AD14: 104760 | AE14: 136240 | AF14: High - SO Supported | AG14: 2026-05-23 | AI14: =IF(OR($H14="Lost",$H14="Dead"),"Lost",IF($I14<>"Y","Excluded",IF($N14<>"","Converted/Partially Converted",IF($J14="","Watchlist","Active")))) -> Converted/Partially Converted | AJ14: =IF($I14<>"Y","Not Eligible - Excluded",IF(OR($H14="Lost",$H14="Dead"),"Not Eligible - Lost",IF($J14="","Scenario Only - No Close Date",IF($X14="","Scenario Only - No Ship Date",IF($Y14="","Scenario Only - No Cash Date",IF($AM14="Y","Not Eligible - SO Mapping Review","Eligible")))))) -> Eligible | AK14: =IF($AJ14="Eligible","Y","N") -> Y | AL14: =SUMIFS(SO_Mapping!$F:$F,SO_Mapping!$A:$A,$B14) -> 104760 | AM14: =IF(AND($N14<>"",$AL14=0),"Y",IF(ABS($O14-$AL14)>1,"Y","N")) -> N | AN14: =MAX(0,$K14-$AL14) -> 136240 | AO14: =IF($AK14="Y","Cash eligible",IF($I14<>"Y","Excluded by control flag",IF($J14="","No expected close date",IF($X14="","No ship/invoice timing",IF($Y14="","No cash timing",IF($AM14="Y","SO mapping must be resolved","Review required")))))) -> Cash eligible | AP14: =IF($AK14="Y",TEXT($Y14,"yyyy-mm-dd"),"") -> 2026-06-12
A15: 18 | B15: DPS-0018 | C15: RO - Replenishment | D15: RO | E15: PRIMARY | F15: Q2 | G15: Jing Santos | H15: Won | I15: Y | J15: 2026-04-16 | K15: 200000 | L15: 0.9 | M15: 180000 | N15: SO2588 | O15: 88161 | P15: 2026-04-16 | Q15: 111839 | R15: 44.1% | S15: Partially Converted | W15: OK | X15: 2026-04-16 | Y15: 2026-05-16 | Z15: 0 | AB15: 2026-05-16 | AC15: SO Linked | AD15: 88161 | AE15: 111839 | AF15: High - SO Supported | AG15: 2026-05-23 | AI15: =IF(OR($H15="Lost",$H15="Dead"),"Lost",IF($I15<>"Y","Excluded",IF($N15<>"","Converted/Partially Converted",IF($J15="","Watchlist","Active")))) -> Converted/Partially Converted | AJ15: =IF($I15<>"Y","Not Eligible - Excluded",IF(OR($H15="Lost",$H15="Dead"),"Not Eligible - Lost",IF($J15="","Scenario Only - No Close Date",IF($X15="","Scenario Only - No Ship Date",IF($Y15="","Scenario Only - No Cash Date",IF($AM15="Y","Not Eligible - SO Mapping Review","Eligible")))))) -> Eligible | AK15: =IF($AJ15="Eligible","Y","N") -> Y | AL15: =SUMIFS(SO_Mapping!$F:$F,SO_Mapping!$A:$A,$B15) -> 88161 | AM15: =IF(AND($N15<>"",$AL15=0),"Y",IF(ABS($O15-$AL15)>1,"Y","N")) -> N | AN15: =MAX(0,$K15-$AL15) -> 111839 | AO15: =IF($AK15="Y","Cash eligible",IF($I15<>"Y","Excluded by control flag",IF($J15="","No expected close date",IF($X15="","No ship/invoice timing",IF($Y15="","No cash timing",IF($AM15="Y","SO mapping must be resolved","Review required")))))) -> Cash eligible | AP15: =IF($AK15="Y",TEXT($Y15,"yyyy-mm-dd"),"") -> 2026-05-16
A16: 19 | B16: DPS-0019 | C16: RO - Replenishment | D16: RO | E16: PRIMARY | F16: Q3 | G16: Jing Santos | H16: Open | I16: Y | K16: 200000 | L16: 0.9 | M16: 180000 | Q16: 200000 | R16: 0.0% | S16: Open | W16: OK | Z16: 0 | AC16: No SO Yet | AD16: 0 | AE16: 200000 | AF16: Low - Missing Timing | AG16: 2026-05-23 | AI16: =IF(OR($H16="Lost",$H16="Dead"),"Lost",IF($I16<>"Y","Excluded",IF($N16<>"","Converted/Partially Converted",IF($J16="","Watchlist","Active")))) -> Watchlist | AJ16: =IF($I16<>"Y","Not Eligible - Excluded",IF(OR($H16="Lost",$H16="Dead"),"Not Eligible - Lost",IF($J16="","Scenario Only - No Close Date",IF($X16="","Scenario Only - No Ship Date",IF($Y16="","Scenario Only - No Cash Date",IF($AM16="Y","Not Eligible - SO Mapping Review","Eligible")))))) -> Scenario Only - No Close Date | AK16: =IF($AJ16="Eligible","Y","N") -> N | AL16: =SUMIFS(SO_Mapping!$F:$F,SO_Mapping!$A:$A,$B16) -> 0 | AM16: =IF(AND($N16<>"",$AL16=0),"Y",IF(ABS($O16-$AL16)>1,"Y","N")) -> N | AN16: =MAX(0,$K16-$AL16) -> 200000 | AO16: =IF($AK16="Y","Cash eligible",IF($I16<>"Y","Excluded by control flag",IF($J16="","No expected close date",IF($X16="","No ship/invoice timing",IF($Y16="","No cash timing",IF($AM16="Y","SO mapping must be resolved","Review required")))))) -> No expected close date | AP16: =IF($AK16="Y",TEXT($Y16,"yyyy-mm-dd"),"")
A17: 20 | B17: DPS-0020 | C17: Pattern Hair Care Line | D17: PATTERN | E17: PRIMARY | F17: Q3 | G17: Jing Santos | H17: Open | I17: Y | K17: 300000 | L17: 0.5 | M17: 150000 | Q17: 300000 | R17: 0.0% | S17: Open | W17: OK | Z17: 0 | AC17: No SO Yet | AD17: 0 | AE17: 300000 | AF17: Low - Missing Timing | AG17: 2026-05-23 | AI17: =IF(OR($H17="Lost",$H17="Dead"),"Lost",IF($I17<>"Y","Excluded",IF($N17<>"","Converted/Partially Converted",IF($J17="","Watchlist","Active")))) -> Watchlist | AJ17: =IF($I17<>"Y","Not Eligible - Excluded",IF(OR($H17="Lost",$H17="Dead"),"Not Eligible - Lost",IF($J17="","Scenario Only - No Close Date",IF($X17="","Scenario Only - No Ship Date",IF($Y17="","Scenario Only - No Cash Date",IF($AM17="Y","Not Eligible - SO Mapping Review","Eligible")))))) -> Scenario Only - No Close Date | AK17: =IF($AJ17="Eligible","Y","N") -> N | AL17: =SUMIFS(SO_Mapping!$F:$F,SO_Mapping!$A:$A,$B17) -> 0 | AM17: =IF(AND($N17<>"",$AL17=0),"Y",IF(ABS($O17-$AL17)>1,"Y","N")) -> N | AN17: =MAX(0,$K17-$AL17) -> 300000 | AO17: =IF($AK17="Y","Cash eligible",IF($I17<>"Y","Excluded by control flag",IF($J17="","No expected close date",IF($X17="","No ship/invoice timing",IF($Y17="","No cash timing",IF($AM17="Y","SO mapping must be resolved","Review required")))))) -> No expected close date | AP17: =IF($AK17="Y",TEXT($Y17,"yyyy-mm-dd"),"")
A18: 22 | B18: DPS-0022 | C18: SWW - Replenishment | D18: SWW | E18: COPACKING | F18: Q3 | G18: Jackie King | H18: Won | I18: Y | J18: 2026-05-15 | K18: 135000 | L18: 0.9 | M18: 121500 | N18: SO2604 | O18: 69832 | P18: 2026-05-15 | Q18: 65168 | R18: 51.7% | S18: Partially Converted | W18: OK | X18: 2026-05-15 | Y18: 2026-06-14 | Z18: 0 | AB18: 2026-06-14 | AC18: SO Linked | AD18: 69832 | AE18: 65168 | AF18: High - SO Supported | AG18: 2026-05-23 | AI18: =IF(OR($H18="Lost",$H18="Dead"),"Lost",IF($I18<>"Y","Excluded",IF($N18<>"","Converted/Partially Converted",IF($J18="","Watchlist","Active")))) -> Converted/Partially Converted | AJ18: =IF($I18<>"Y","Not Eligible - Excluded",IF(OR($H18="Lost",$H18="Dead"),"Not Eligible - Lost",IF($J18="","Scenario Only - No Close Date",IF($X18="","Scenario Only - No Ship Date",IF($Y18="","Scenario Only - No Cash Date",IF($AM18="Y","Not Eligible - SO Mapping Review","Eligible")))))) -> Eligible | AK18: =IF($AJ18="Eligible","Y","N") -> Y | AL18: =SUMIFS(SO_Mapping!$F:$F,SO_Mapping!$A:$A,$B18) -> 69832 | AM18: =IF(AND($N18<>"",$AL18=0),"Y",IF(ABS($O18-$AL18)>1,"Y","N")) -> N | AN18: =MAX(0,$K18-$AL18) -> 65168 | AO18: =IF($AK18="Y","Cash eligible",IF($I18<>"Y","Excluded by control flag",IF($J18="","No expected close date",IF($X18="","No ship/invoice timing",IF($Y18="","No cash timing",IF($AM18="Y","SO mapping must be resolved","Review required")))))) -> Cash eligible | AP18: =IF($AK18="Y",TEXT($Y18,"yyyy-mm-dd"),"") -> 2026-06-14
A19: 23 | B19: DPS-0023 | C19: SWW - Replenishment | D19: SWW | E19: COPACKING | F19: Q4 | G19: Jackie King | H19: Open | I19: Y | K19: 135000 | L19: 0.9 | M19: 121500 | Q19: 135000 | R19: 0.0% | S19: Open | W19: OK | Z19: 0 | AC19: No SO Yet | AD19: 0 | AE19: 135000 | AF19: Low - Missing Timing | AG19: 2026-05-23 | AI19: =IF(OR($H19="Lost",$H19="Dead"),"Lost",IF($I19<>"Y","Excluded",IF($N19<>"","Converted/Partially Converted",IF($J19="","Watchlist","Active")))) -> Watchlist | AJ19: =IF($I19<>"Y","Not Eligible - Excluded",IF(OR($H19="Lost",$H19="Dead"),"Not Eligible - Lost",IF($J19="","Scenario Only - No Close Date",IF($X19="","Scenario Only - No Ship Date",IF($Y19="","Scenario Only - No Cash Date",IF($AM19="Y","Not Eligible - SO Mapping Review","Eligible")))))) -> Scenario Only - No Close Date | AK19: =IF($AJ19="Eligible","Y","N") -> N | AL19: =SUMIFS(SO_Mapping!$F:$F,SO_Mapping!$A:$A,$B19) -> 0 | AM19: =IF(AND($N19<>"",$AL19=0),"Y",IF(ABS($O19-$AL19)>1,"Y","N")) -> N | AN19: =MAX(0,$K19-$AL19) -> 135000 | AO19: =IF($AK19="Y","Cash eligible",IF($I19<>"Y","Excluded by control flag",IF($J19="","No expected close date",IF($X19="","No ship/invoice timing",IF($Y19="","No cash timing",IF($AM19="Y","SO mapping must be resolved","Review required")))))) -> No expected close date | AP19: =IF($AK19="Y",TEXT($Y19,"yyyy-mm-dd"),"")
A20: 24 | B20: DPS-0024 | C20: Ritual Fragrance Mist | D20: CIRQADIAN | E20: TURNKEY | F20: Q3 | G20: Danny Park | H20: Won | I20: Y | J20: 2026-03-25 | K20: 120000 | L20: 1 | M20: 120000 | N20: SO2527, 2578, 2580, 2581, 2582 | O20: 235494 | P20: 2026-03-25 | R20: 196.2% | S20: Fully Converted | W20: Review SO over pipeline | X20: 2026-03-25 | Y20: 2026-04-24 | Z20: 0 | AB20: 2026-04-24 | AC20: SO Linked | AD20: 235494 | AE20: 0 | AF20: Do Not Use - Data Issue | AG20: 2026-05-23 | AI20: =IF(OR($H20="Lost",$H20="Dead"),"Lost",IF($I20<>"Y","Excluded",IF($N20<>"","Converted/Partially Converted",IF($J20="","Watchlist","Active")))) -> Converted/Partially Converted | AJ20: =IF($I20<>"Y","Not Eligible - Excluded",IF(OR($H20="Lost",$H20="Dead"),"Not Eligible - Lost",IF($J20="","Scenario Only - No Close Date",IF($X20="","Scenario Only - No Ship Date",IF($Y20="","Scenario Only - No Cash Date",IF($AM20="Y","Not Eligible - SO Mapping Review","Eligible")))))) -> Not Eligible - SO Mapping Review | AK20: =IF($AJ20="Eligible","Y","N") -> N | AL20: =SUMIFS(SO_Mapping!$F:$F,SO_Mapping!$A:$A,$B20) -> 0 | AM20: =IF(AND($N20<>"",$AL20=0),"Y",IF(ABS($O20-$AL20)>1,"Y","N")) -> Y | AN20: =MAX(0,$K20-$AL20) -> 120000 | AO20: =IF($AK20="Y","Cash eligible",IF($I20<>"Y","Excluded by control flag",IF($J20="","No expected close date",IF($X20="","No ship/invoice timing",IF($Y20="","No cash timing",IF($AM20="Y","SO mapping must be resolved","Review required")))))) -> SO mapping must be resolved | AP20: =IF($AK20="Y",TEXT($Y20,"yyyy-mm-dd"),"")
A21: 25 | B21: DPS-0025 | C21: COLOGNE BOXES - Replenishment | D21: DRSQ | E21: SOFT GOODS | F21: Q2 | G21: Danny Park | H21: Won | I21: Y | J21: 2026-01-16 | K21: 149215 | L21: 0.75 | M21: 111911 | N21: SO2538 | O21: 149215 | P21: 2026-01-16 | R21: 100.0% | S21: Fully Converted | W21: OK | X21: 2026-01-16 | Y21: 2026-02-15 | Z21: 0 | AB21: 2026-02-15 | AC21: SO Linked | AD21: 149215 | AE21: 0 | AF21: High - SO Supported | AG21: 2026-05-23 | AI21: =IF(OR($H21="Lost",$H21="Dead"),"Lost",IF($I21<>"Y","Excluded",IF($N21<>"","Converted/Partially Converted",IF($J21="","Watchlist","Active")))) -> Converted/Partially Converted | AJ21: =IF($I21<>"Y","Not Eligible - Excluded",IF(OR($H21="Lost",$H21="Dead"),"Not Eligible - Lost",IF($J21="","Scenario Only - No Close Date",IF($X21="","Scenario Only - No Ship Date",IF($Y21="","Scenario Only - No Cash Date",IF($AM21="Y","Not Eligible - SO Mapping Review","Eligible")))))) -> Eligible | AK21: =IF($AJ21="Eligible","Y","N") -> Y | AL21: =SUMIFS(SO_Mapping!$F:$F,SO_Mapping!$A:$A,$B21) -> 149215 | AM21: =IF(AND($N21<>"",$AL21=0),"Y",IF(ABS($O21-$AL21)>1,"Y","N")) -> N | AN21: =MAX(0,$K21-$AL21) -> 0 | AO21: =IF($AK21="Y","Cash eligible",IF($I21<>"Y","Excluded by control flag",IF($J21="","No expected close date",IF($X21="","No ship/invoice timing",IF($Y21="","No cash timing",IF($AM21="Y","SO mapping must be resolved","Review required")))))) -> Cash eligible | AP21: =IF($AK21="Y",TEXT($Y21,"yyyy-mm-dd"),"") -> 2026-02-15
A22: 26 | B22: DPS-0026 | C22: KONJAC JELLY | D22: TEVIS | E22: TURNKEY | F22: Q3 | G22: Jackie King | H22: Open | I22: Y | K22: 200000 | L22: 0.5 | M22: 100000 | Q22: 200000 | R22: 0.0% | S22: Open | W22: OK | Z22: 0 | AC22: No SO Yet | AD22: 0 | AE22: 200000 | AF22: Low - Missing Timing | AG22: 2026-05-23 | AI22: =IF(OR($H22="Lost",$H22="Dead"),"Lost",IF($I22<>"Y","Excluded",IF($N22<>"","Converted/Partially Converted",IF($J22="","Watchlist","Active")))) -> Watchlist | AJ22: =IF($I22<>"Y","Not Eligible - Excluded",IF(OR($H22="Lost",$H22="Dead"),"Not Eligible - Lost",IF($J22="","Scenario Only - No Close Date",IF($X22="","Scenario Only - No Ship Date",IF($Y22="","Scenario Only - No Cash Date",IF($AM22="Y","Not Eligible - SO Mapping Review","Eligible")))))) -> Scenario Only - No Close Date | AK22: =IF($AJ22="Eligible","Y","N") -> N | AL22: =SUMIFS(SO_Mapping!$F:$F,SO_Mapping!$A:$A,$B22) -> 0 | AM22: =IF(AND($N22<>"",$AL22=0),"Y",IF(ABS($O22-$AL22)>1,"Y","N")) -> N | AN22: =MAX(0,$K22-$AL22) -> 200000 | AO22: =IF($AK22="Y","Cash eligible",IF($I22<>"Y","Excluded by control flag",IF($J22="","No expected close date",IF($X22="","No ship/invoice timing",IF($Y22="","No cash timing",IF($AM22="Y","SO mapping must be resolved","Review required")))))) -> No expected close date | AP22: =IF($AK22="Y",TEXT($Y22,"yyyy-mm-dd"),"")
A23: 27 | B23: DPS-0027 | C23: BRAIN MD - Replenishment | D23: BRAIN MD | E23: TURNKEY | F23: Q2 | G23: Jackie King | H23: Won | I23: Y | J23: 2026-01-01 | K23: 100000 | L23: 0.9 | M23: 90000 | N23: SO2525, 2511 | O23: 129603 | P23: 2026-01-01 | R23: 129.6% | S23: Fully Converted | W23: Review SO over pipeline | X23: 2026-01-01 | Y23: 2026-01-31 | Z23: 0 | AB23: 2026-01-31 | AC23: SO Linked | AD23: 129603 | AE23: 0 | AF23: Do Not Use - Data Issue | AG23: 2026-05-23 | AI23: =IF(OR($H23="Lost",$H23="Dead"),"Lost",IF($I23<>"Y","Excluded",IF($N23<>"","Converted/Partially Converted",IF($J23="","Watchlist","Active")))) -> Converted/Partially Converted | AJ23: =IF($I23<>"Y","Not Eligible - Excluded",IF(OR($H23="Lost",$H23="Dead"),"Not Eligible - Lost",IF($J23="","Scenario Only - No Close Date",IF($X23="","Scenario Only - No Ship Date",IF($Y23="","Scenario Only - No Cash Date",IF($AM23="Y","Not Eligible - SO Mapping Review","Eligible")))))) -> Not Eligible - SO Mapping Review | AK23: =IF($AJ23="Eligible","Y","N") -> N | AL23: =SUMIFS(SO_Mapping!$F:$F,SO_Mapping!$A:$A,$B23) -> 0 | AM23: =IF(AND($N23<>"",$AL23=0),"Y",IF(ABS($O23-$AL23)>1,"Y","N")) -> Y | AN23: =MAX(0,$K23-$AL23) -> 100000 | AO23: =IF($AK23="Y","Cash eligible",IF($I23<>"Y","Excluded by control flag",IF($J23="","No expected close date",IF($X23="","No ship/invoice timing",IF($Y23="","No cash timing",IF($AM23="Y","SO mapping must be resolved","Review required")))))) -> SO mapping must be resolved | AP23: =IF($AK23="Y",TEXT($Y23,"yyyy-mm-dd"),"")
A24: 28 | B24: DPS-0028 | C24: BRAIN MD - Replenishment | D24: BRAIN MD | E24: TURNKEY | F24: Q3 | G24: Jackie King | H24: Open | I24: Y | K24: 100000 | L24: 0.9 | M24: 90000 | Q24: 100000 | R24: 0.0% | S24: Open | W24: OK | Z24: 0 | AC24: No SO Yet | AD24: 0 | AE24: 100000 | AF24: Low - Missing Timing | AG24: 2026-05-23 | AI24: =IF(OR($H24="Lost",$H24="Dead"),"Lost",IF($I24<>"Y","Excluded",IF($N24<>"","Converted/Partially Converted",IF($J24="","Watchlist","Active")))) -> Watchlist | AJ24: =IF($I24<>"Y","Not Eligible - Excluded",IF(OR($H24="Lost",$H24="Dead"),"Not Eligible - Lost",IF($J24="","Scenario Only - No Close Date",IF($X24="","Scenario Only - No Ship Date",IF($Y24="","Scenario Only - No Cash Date",IF($AM24="Y","Not Eligible - SO Mapping Review","Eligible")))))) -> Scenario Only - No Close Date | AK24: =IF($AJ24="Eligible","Y","N") -> N | AL24: =SUMIFS(SO_Mapping!$F:$F,SO_Mapping!$A:$A,$B24) -> 0 | AM24: =IF(AND($N24<>"",$AL24=0),"Y",IF(ABS($O24-$AL24)>1,"Y","N")) -> N | AN24: =MAX(0,$K24-$AL24) -> 100000 | AO24: =IF($AK24="Y","Cash eligible",IF($I24<>"Y","Excluded by control flag",IF($J24="","No expected close date",IF($X24="","No ship/invoice timing",IF($Y24="","No cash timing",IF($AM24="Y","SO mapping must be resolved","Review required")))))) -> No expected close date | AP24: =IF($AK24="Y",TEXT($Y24,"yyyy-mm-dd"),"")
A25: 29 | B25: DPS-0029 | C25: Pattern - Replenishment | D25: PATTERN | E25: PRIMARY | F25: Q2 | G25: Jing Santos | H25: Open | I25: Y | K25: 90000 | L25: 0.9 | M25: 81000 | Q25: 90000 | R25: 0.0% | S25: Open | W25: OK | Z25: 0 | AC25: No SO Yet | AD25: 0 | AE25: 90000 | AF25: Low - Missing Timing | AG25: 2026-05-23 | AI25: =IF(OR($H25="Lost",$H25="Dead"),"Lost",IF($I25<>"Y","Excluded",IF($N25<>"","Converted/Partially Converted",IF($J25="","Watchlist","Active")))) -> Watchlist | AJ25: =IF($I25<>"Y","Not Eligible - Excluded",IF(OR($H25="Lost",$H25="Dead"),"Not Eligible - Lost",IF($J25="","Scenario Only - No Close Date",IF($X25="","Scenario Only - No Ship Date",IF($Y25="","Scenario Only - No Cash Date",IF($AM25="Y","Not Eligible - SO Mapping Review","Eligible")))))) -> Scenario Only - No Close Date | AK25: =IF($AJ25="Eligible","Y","N") -> N | AL25: =SUMIFS(SO_Mapping!$F:$F,SO_Mapping!$A:$A,$B25) -> 0 | AM25: =IF(AND($N25<>"",$AL25=0),"Y",IF(ABS($O25-$AL25)>1,"Y","N")) -> N | AN25: =MAX(0,$K25-$AL25) -> 90000 | AO25: =IF($AK25="Y","Cash eligible",IF($I25<>"Y","Excluded by control flag",IF($J25="","No expected close date",IF($X25="","No ship/invoice timing",IF($Y25="","No cash timing",IF($AM25="Y","SO mapping must be resolved","Review required")))))) -> No expected close date | AP25: =IF($AK25="Y",TEXT($Y25,"yyyy-mm-dd"),"")
A26: 30 | B26: DPS-0030 | C26: Pattern - Replenishment | D26: PATTERN | E26: PRIMARY | F26: Q3 | G26: Jing Santos | H26: Open | I26: Y | K26: 90000 | L26: 0.9 | M26: 81000 | Q26: 90000 | R26: 0.0% | S26: Open | W26: OK | Z26: 0 | AC26: No SO Yet | AD26: 0 | AE26: 90000 | AF26: Low - Missing Timing | AG26: 2026-05-23 | AI26: =IF(OR($H26="Lost",$H26="Dead"),"Lost",IF($I26<>"Y","Excluded",IF($N26<>"","Converted/Partially Converted",IF($J26="","Watchlist","Active")))) -> Watchlist | AJ26: =IF($I26<>"Y","Not Eligible - Excluded",IF(OR($H26="Lost",$H26="Dead"),"Not Eligible - Lost",IF($J26="","Scenario Only - No Close Date",IF($X26="","Scenario Only - No Ship Date",IF($Y26="","Scenario Only - No Cash Date",IF($AM26="Y","Not Eligible - SO Mapping Review","Eligible")))))) -> Scenario Only - No Close Date | AK26: =IF($AJ26="Eligible","Y","N") -> N | AL26: =SUMIFS(SO_Mapping!$F:$F,SO_Mapping!$A:$A,$B26) -> 0 | AM26: =IF(AND($N26<>"",$AL26=0),"Y",IF(ABS($O26-$AL26)>1,"Y","N")) -> N | AN26: =MAX(0,$K26-$AL26) -> 90000 | AO26: =IF($AK26="Y","Cash eligible",IF($I26<>"Y","Excluded by control flag",IF($J26="","No expected close date",IF($X26="","No ship/invoice timing",IF($Y26="","No cash timing",IF($AM26="Y","SO mapping must be resolved","Review required")))))) -> No expected close date | AP26: =IF($AK26="Y",TEXT($Y26,"yyyy-mm-dd"),"")
A27: 31 | B27: DPS-0031 | C27: Pattern - Replenishment | D27: PATTERN | E27: PRIMARY | F27: Q4 | G27: Jing Santos | H27: Open | I27: Y | K27: 90000 | L27: 0.9 | M27: 81000 | Q27: 90000 | R27: 0.0% | S27: Open | W27: OK | Z27: 0 | AC27: No SO Yet | AD27: 0 | AE27: 90000 | AF27: Low - Missing Timing | AG27: 2026-05-23 | AI27: =IF(OR($H27="Lost",$H27="Dead"),"Lost",IF($I27<>"Y","Excluded",IF($N27<>"","Converted/Partially Converted",IF($J27="","Watchlist","Active")))) -> Watchlist | AJ27: =IF($I27<>"Y","Not Eligible - Excluded",IF(OR($H27="Lost",$H27="Dead"),"Not Eligible - Lost",IF($J27="","Scenario Only - No Close Date",IF($X27="","Scenario Only - No Ship Date",IF($Y27="","Scenario Only - No Cash Date",IF($AM27="Y","Not Eligible - SO Mapping Review","Eligible")))))) -> Scenario Only - No Close Date | AK27: =IF($AJ27="Eligible","Y","N") -> N | AL27: =SUMIFS(SO_Mapping!$F:$F,SO_Mapping!$A:$A,$B27) -> 0 | AM27: =IF(AND($N27<>"",$AL27=0),"Y",IF(ABS($O27-$AL27)>1,"Y","N")) -> N | AN27: =MAX(0,$K27-$AL27) -> 90000 | AO27: =IF($AK27="Y","Cash eligible",IF($I27<>"Y","Excluded by control flag",IF($J27="","No expected close date",IF($X27="","No ship/invoice timing",IF($Y27="","No cash timing",IF($AM27="Y","SO mapping must be resolved","Review required")))))) -> No expected close date | AP27: =IF($AK27="Y",TEXT($Y27,"yyyy-mm-dd"),"")
A28: 32 | B28: DPS-0032 | C28: I&R - Replenishment | D28: I&R | E28: PRIMARY | F28: Q2 | G28: Jing Santos | H28: Won | I28: Y | J28: 2026-01-01 | K28: 90000 | L28: 0.9 | M28: 81000 | N28: SO2509, 2566 | O28: 102846.84 | P28: 2026-01-01 | R28: 114.3% | S28: Fully Converted | W28: OK | X28: 2026-01-01 | Y28: 2026-01-31 | Z28: 0 | AB28: 2026-01-31 | AC28: SO Linked | AD28: 102846.84 | AE28: 0 | AF28: High - SO Supported | AG28: 2026-05-23 | AI28: =IF(OR($H28="Lost",$H28="Dead"),"Lost",IF($I28<>"Y","Excluded",IF($N28<>"","Converted/Partially Converted",IF($J28="","Watchlist","Active")))) -> Converted/Partially Converted | AJ28: =IF($I28<>"Y","Not Eligible - Excluded",IF(OR($H28="Lost",$H28="Dead"),"Not Eligible - Lost",IF($J28="","Scenario Only - No Close Date",IF($X28="","Scenario Only - No Ship Date",IF($Y28="","Scenario Only - No Cash Date",IF($AM28="Y","Not Eligible - SO Mapping Review","Eligible")))))) -> Not Eligible - SO Mapping Review | AK28: =IF($AJ28="Eligible","Y","N") -> N | AL28: =SUMIFS(SO_Mapping!$F:$F,SO_Mapping!$A:$A,$B28) -> 0 | AM28: =IF(AND($N28<>"",$AL28=0),"Y",IF(ABS($O28-$AL28)>1,"Y","N")) -> Y | AN28: =MAX(0,$K28-$AL28) -> 90000 | AO28: =IF($AK28="Y","Cash eligible",IF($I28<>"Y","Excluded by control flag",IF($J28="","No expected close date",IF($X28="","No ship/invoice timing",IF($Y28="","No cash timing",IF($AM28="Y","SO mapping must be resolved","Review required")))))) -> SO mapping must be resolved | AP28: =IF($AK28="Y",TEXT($Y28,"yyyy-mm-dd"),"")
A29: 33 | B29: DPS-0033 | C29: I&R - Replenishment | D29: I&R | E29: PRIMARY | F29: Q2 | G29: Jing Santos | H29: Lost | I29: Y | K29: 90000 | L29: 0.9 | M29: 81000 | Q29: 90000 | R29: 0.0% | S29: Lost | W29: OK | Z29: 0 | AC29: No SO Yet | AD29: 0 | AE29: 90000 | AF29: Low - Missing Timing | AG29: 2026-05-23 | AI29: =IF(OR($H29="Lost",$H29="Dead"),"Lost",IF($I29<>"Y","Excluded",IF($N29<>"","Converted/Partially Converted",IF($J29="","Watchlist","Active")))) -> Lost | AJ29: =IF($I29<>"Y","Not Eligible - Excluded",IF(OR($H29="Lost",$H29="Dead"),"Not Eligible - Lost",IF($J29="","Scenario Only - No Close Date",IF($X29="","Scenario Only - No Ship Date",IF($Y29="","Scenario Only - No Cash Date",IF($AM29="Y","Not Eligible - SO Mapping Review","Eligible")))))) -> Not Eligible - Lost | AK29: =IF($AJ29="Eligible","Y","N") -> N | AL29: =SUMIFS(SO_Mapping!$F:$F,SO_Mapping!$A:$A,$B29) -> 0 | AM29: =IF(AND($N29<>"",$AL29=0),"Y",IF(ABS($O29-$AL29)>1,"Y","N")) -> N | AN29: =MAX(0,$K29-$AL29) -> 90000 | AO29: =IF($AK29="Y","Cash eligible",IF($I29<>"Y","Excluded by control flag",IF($J29="","No expected close date",IF($X29="","No ship/invoice timing",IF($Y29="","No cash timing",IF($AM29="Y","SO mapping must be resolved","Review required")))))) -> No expected close date | AP29: =IF($AK29="Y",TEXT($Y29,"yyyy-mm-dd"),"")
A30: 34 | B30: DPS-0034 | C30: I&R - Replenishment | D30: I&R | E30: PRIMARY | F30: Q3 | G30: Jing Santos | H30: Open | I30: Y | K30: 90000 | L30: 0.9 | M30: 81000 | Q30: 90000 | R30: 0.0% | S30: Open | W30: OK | Z30: 0 | AC30: No SO Yet | AD30: 0 | AE30: 90000 | AF30: Low - Missing Timing | AG30: 2026-05-23 | AI30: =IF(OR($H30="Lost",$H30="Dead"),"Lost",IF($I30<>"Y","Excluded",IF($N30<>"","Converted/Partially Converted",IF($J30="","Watchlist","Active")))) -> Watchlist | AJ30: =IF($I30<>"Y","Not Eligible - Excluded",IF(OR($H30="Lost",$H30="Dead"),"Not Eligible - Lost",IF($J30="","Scenario Only - No Close Date",IF($X30="","Scenario Only - No Ship Date",IF($Y30="","Scenario Only - No Cash Date",IF($AM30="Y","Not Eligible - SO Mapping Review","Eligible")))))) -> Scenario Only - No Close Date | AK30: =IF($AJ30="Eligible","Y","N") -> N | AL30: =SUMIFS(SO_Mapping!$F:$F,SO_Mapping!$A:$A,$B30) -> 0 | AM30: =IF(AND($N30<>"",$AL30=0),"Y",IF(ABS($O30-$AL30)>1,"Y","N")) -> N | AN30: =MAX(0,$K30-$AL30) -> 90000 | AO30: =IF($AK30="Y","Cash eligible",IF($I30<>"Y","Excluded by control flag",IF($J30="","No expected close date",IF($X30="","No ship/invoice timing",IF($Y30="","No cash timing",IF($AM30="Y","SO mapping must be resolved","Review required")))))) -> No expected close date | AP30: =IF($AK30="Y",TEXT($Y30,"yyyy-mm-dd"),"")
A31: 35 | B31: DPS-0035 | C31: I&R - Replenishment | D31: I&R | E31: PRIMARY | F31: Q4 | G31: Jing Santos | H31: Open | I31: Y | K31: 90000 | L31: 0.9 | M31: 81000 | Q31: 90000 | R31: 0.0% | S31: Open | W31: OK | Z31: 0 | AC31: No SO Yet | AD31: 0 | AE31: 90000 | AF31: Low - Missing Timing | AG31: 2026-05-23 | AI31: =IF(OR($H31="Lost",$H31="Dead"),"Lost",IF($I31<>"Y","Excluded",IF($N31<>"","Converted/Partially Converted",IF($J31="","Watchlist","Active")))) -> Watchlist | AJ31: =IF($I31<>"Y","Not Eligible - Excluded",IF(OR($H31="Lost",$H31="Dead"),"Not Eligible - Lost",IF($J31="","Scenario Only - No Close Date",IF($X31="","Scenario Only - No Ship Date",IF($Y31="","Scenario Only - No Cash Date",IF($AM31="Y","Not Eligible - SO Mapping Review","Eligible")))))) -> Scenario Only - No Close Date | AK31: =IF($AJ31="Eligible","Y","N") -> N | AL31: =SUMIFS(SO_Mapping!$F:$F,SO_Mapping!$A:$A,$B31) -> 0 | AM31: =IF(AND($N31<>"",$AL31=0),"Y",IF(ABS($O31-$AL31)>1,"Y","N")) -> N | AN31: =MAX(0,$K31-$AL31) -> 90000 | AO31: =IF($AK31="Y","Cash eligible",IF($I31<>"Y","Excluded by control flag",IF($J31="","No expected close date",IF($X31="","No ship/invoice timing",IF($Y31="","No cash timing",IF($AM31="Y","SO mapping must be resolved","Review required")))))) -> No expected close date | AP31: =IF($AK31="Y",TEXT($Y31,"yyyy-mm-dd"),"")
A32: 36 | B32: DPS-0036 | C32: SWW - Replenishment | D32: SWW | E32: COPACKING | F32: Q2 | G32: Jackie King | H32: Won | I32: Y | J32: 2026-02-11 | K32: 85000 | L32: 0.9 | M32: 76500 | N32: SO2560 | O32: 33908.75 | P32: 2026-02-11 | Q32: 51091 | R32: 39.9% | S32: Partially Converted | W32: OK | X32: 2026-02-11 | Y32: 2026-03-13 | Z32: 0 | AB32: 2026-03-13 | AC32: SO Linked | AD32: 33908.75 | AE32: 51091.25 | AF32: High - SO Supported | AG32: 2026-05-23 | AI32: =IF(OR($H32="Lost",$H32="Dead"),"Lost",IF($I32<>"Y","Excluded",IF($N32<>"","Converted/Partially Converted",IF($J32="","Watchlist","Active")))) -> Converted/Partially Converted | AJ32: =IF($I32<>"Y","Not Eligible - Excluded",IF(OR($H32="Lost",$H32="Dead"),"Not Eligible - Lost",IF($J32="","Scenario Only - No Close Date",IF($X32="","Scenario Only - No Ship Date",IF($Y32="","Scenario Only - No Cash Date",IF($AM32="Y","Not Eligible - SO Mapping Review","Eligible")))))) -> Eligible | AK32: =IF($AJ32="Eligible","Y","N") -> Y | AL32: =SUMIFS(SO_Mapping!$F:$F,SO_Mapping!$A:$A,$B32) -> 33908.75 | AM32: =IF(AND($N32<>"",$AL32=0),"Y",IF(ABS($O32-$AL32)>1,"Y","N")) -> N | AN32: =MAX(0,$K32-$AL32) -> 51091.25 | AO32: =IF($AK32="Y","Cash eligible",IF($I32<>"Y","Excluded by control flag",IF($J32="","No expected close date",IF($X32="","No ship/invoice timing",IF($Y32="","No cash timing",IF($AM32="Y","SO mapping must be resolved","Review required")))))) -> Cash eligible | AP32: =IF($AK32="Y",TEXT($Y32,"yyyy-mm-dd"),"") -> 2026-03-13
A33: 37 | B33: DPS-0037 | C33: 5pk Mini Cologne Kit | D33: DRSQ | E33: SECONDARY | F33: Q3 | G33: Danny Park | H33: Open | I33: Y | K33: 150000 | L33: 0.5 | M33: 75000 | Q33: 150000 | R33: 0.0% | S33: Open | W33: OK | Z33: 0 | AC33: No SO Yet | AD33: 0 | AE33: 150000 | AF33: Low - Missing Timing | AG33: 2026-05-23 | AI33: =IF(OR($H33="Lost",$H33="Dead"),"Lost",IF($I33<>"Y","Excluded",IF($N33<>"","Converted/Partially Converted",IF($J33="","Watchlist","Active")))) -> Watchlist | AJ33: =IF($I33<>"Y","Not Eligible - Excluded",IF(OR($H33="Lost",$H33="Dead"),"Not Eligible - Lost",IF($J33="","Scenario Only - No Close Date",IF($X33="","Scenario Only - No Ship Date",IF($Y33="","Scenario Only - No Cash Date",IF($AM33="Y","Not Eligible - SO Mapping Review","Eligible")))))) -> Scenario Only - No Close Date | AK33: =IF($AJ33="Eligible","Y","N") -> N | AL33: =SUMIFS(SO_Mapping!$F:$F,SO_Mapping!$A:$A,$B33) -> 0 | AM33: =IF(AND($N33<>"",$AL33=0),"Y",IF(ABS($O33-$AL33)>1,"Y","N")) -> N | AN33: =MAX(0,$K33-$AL33) -> 150000 | AO33: =IF($AK33="Y","Cash eligible",IF($I33<>"Y","Excluded by control flag",IF($J33="","No expected close date",IF($X33="","No ship/invoice timing",IF($Y33="","No cash timing",IF($AM33="Y","SO mapping must be resolved","Review required")))))) -> No expected close date | AP33: =IF($AK33="Y",TEXT($Y33,"yyyy-mm-dd"),"")
A34: 38 | B34: DPS-0038 | C34: 100ML OTG Cologne | D34: GET W | E34: TURNKEY | F34: Q3 | G34: Jing Santos | H34: Open | I34: Y | K34: 150000 | L34: 0.5 | M34: 75000 | Q34: 150000 | R34: 0.0% | S34: Open | W34: OK | Z34: 0 | AC34: No SO Yet | AD34: 0 | AE34: 150000 | AF34: Low - Missing Timing | AG34: 2026-05-23 | AI34: =IF(OR($H34="Lost",$H34="Dead"),"Lost",IF($I34<>"Y","Excluded",IF($N34<>"","Converted/Partially Converted",IF($J34="","Watchlist","Active")))) -> Watchlist | AJ34: =IF($I34<>"Y","Not Eligible - Excluded",IF(OR($H34="Lost",$H34="Dead"),"Not Eligible - Lost",IF($J34="","Scenario Only - No Close Date",IF($X34="","Scenario Only - No Ship Date",IF($Y34="","Scenario Only - No Cash Date",IF($AM34="Y","Not Eligible - SO Mapping Review","Eligible")))))) -> Scenario Only - No Close Date | AK34: =IF($AJ34="Eligible","Y","N") -> N | AL34: =SUMIFS(SO_Mapping!$F:$F,SO_Mapping!$A:$A,$B34) -> 0 | AM34: =IF(AND($N34<>"",$AL34=0),"Y",IF(ABS($O34-$AL34)>1,"Y","N")) -> N | AN34: =MAX(0,$K34-$AL34) -> 150000 | AO34: =IF($AK34="Y","Cash eligible",IF($I34<>"Y","Excluded by control flag",IF($J34="","No expected close date",IF($X34="","No ship/invoice timing",IF($Y34="","No cash timing",IF($AM34="Y","SO mapping must be resolved","Review required")))))) -> No expected close date | AP34: =IF($AK34="Y",TEXT($Y34,"yyyy-mm-dd"),"")
A35: 39 | B35: DPS-0039 | C35: Sample Pack - Silk Rinse | D35: CECRED | E35: COPACKING | F35: Q2 | G35: Jackie King | H35: Won | I35: Y | J35: 2026-05-11 | K35: 75000 | L35: 0.9 | M35: 67500 | N35: SO2603, 2604 | O35: 27122 | P35: 2026-05-11 | Q35: 47878 | R35: 36.2% | S35: Partially Converted | W35: OK | X35: 2026-05-11 | Y35: 2026-06-10 | Z35: 0 | AB35: 2026-06-10 | AC35: SO Linked | AD35: 27122 | AE35: 47878 | AF35: High - SO Supported | AG35: 2026-05-23 | AI35: =IF(OR($H35="Lost",$H35="Dead"),"Lost",IF($I35<>"Y","Excluded",IF($N35<>"","Converted/Partially Converted",IF($J35="","Watchlist","Active")))) -> Converted/Partially Converted | AJ35: =IF($I35<>"Y","Not Eligible - Excluded",IF(OR($H35="Lost",$H35="Dead"),"Not Eligible - Lost",IF($J35="","Scenario Only - No Close Date",IF($X35="","Scenario Only - No Ship Date",IF($Y35="","Scenario Only - No Cash Date",IF($AM35="Y","Not Eligible - SO Mapping Review","Eligible")))))) -> Not Eligible - SO Mapping Review | AK35: =IF($AJ35="Eligible","Y","N") -> N | AL35: =SUMIFS(SO_Mapping!$F:$F,SO_Mapping!$A:$A,$B35) -> 0 | AM35: =IF(AND($N35<>"",$AL35=0),"Y",IF(ABS($O35-$AL35)>1,"Y","N")) -> Y | AN35: =MAX(0,$K35-$AL35) -> 75000 | AO35: =IF($AK35="Y","Cash eligible",IF($I35<>"Y","Excluded by control flag",IF($J35="","No expected close date",IF($X35="","No ship/invoice timing",IF($Y35="","No cash timing",IF($AM35="Y","SO mapping must be resolved","Review required")))))) -> SO mapping must be resolved | AP35: =IF($AK35="Y",TEXT($Y35,"yyyy-mm-dd"),"")
A36: 40 | B36: DPS-0040 | C36: Ritual Fragrance Mist | D36: CIRQADIAN | E36: TURNKEY | F36: Q4 | G36: Danny Park | H36: Open | I36: Y | K36: 120000 | L36: 0.5 | M36: 60000 | Q36: 120000 | R36: 0.0% | S36: Open | W36: OK | Z36: 0 | AC36: No SO Yet | AD36: 0 | AE36: 120000 | AF36: Low - Missing Timing | AG36: 2026-05-23 | AI36: =IF(OR($H36="Lost",$H36="Dead"),"Lost",IF($I36<>"Y","Excluded",IF($N36<>"","Converted/Partially Converted",IF($J36="","Watchlist","Active")))) -> Watchlist | AJ36: =IF($I36<>"Y","Not Eligible - Excluded",IF(OR($H36="Lost",$H36="Dead"),"Not Eligible - Lost",IF($J36="","Scenario Only - No Close Date",IF($X36="","Scenario Only - No Ship Date",IF($Y36="","Scenario Only - No Cash Date",IF($AM36="Y","Not Eligible - SO Mapping Review","Eligible")))))) -> Scenario Only - No Close Date | AK36: =IF($AJ36="Eligible","Y","N") -> N | AL36: =SUMIFS(SO_Mapping!$F:$F,SO_Mapping!$A:$A,$B36) -> 0 | AM36: =IF(AND($N36<>"",$AL36=0),"Y",IF(ABS($O36-$AL36)>1,"Y","N")) -> N | AN36: =MAX(0,$K36-$AL36) -> 120000 | AO36: =IF($AK36="Y","Cash eligible",IF($I36<>"Y","Excluded by control flag",IF($J36="","No expected close date",IF($X36="","No ship/invoice timing",IF($Y36="","No cash timing",IF($AM36="Y","SO mapping must be resolved","Review required")))))) -> No expected close date | AP36: =IF($AK36="Y",TEXT($Y36,"yyyy-mm-dd"),"")
A37: 41 | B37: DPS-0041 | C37: SWW - Replenishment | D37: SWW | E37: COPACKING | F37: Q1 | G37: Jackie King | H37: Won | I37: Y | J37: 2026-02-25 | K37: 60000 | L37: 0.85 | M37: 51000 | N37: SO2565 | O37: 61098 | P37: 2026-02-25 | R37: 101.8% | S37: Fully Converted | W37: OK | X37: 2026-02-25 | Y37: 2026-03-27 | Z37: 0 | AB37: 2026-03-27 | AC37: SO Linked | AD37: 61098 | AE37: 0 | AF37: High - SO Supported | AG37: 2026-05-23 | AI37: =IF(OR($H37="Lost",$H37="Dead"),"Lost",IF($I37<>"Y","Excluded",IF($N37<>"","Converted/Partially Converted",IF($J37="","Watchlist","Active")))) -> Converted/Partially Converted | AJ37: =IF($I37<>"Y","Not Eligible - Excluded",IF(OR($H37="Lost",$H37="Dead"),"Not Eligible - Lost",IF($J37="","Scenario Only - No Close Date",IF($X37="","Scenario Only - No Ship Date",IF($Y37="","Scenario Only - No Cash Date",IF($AM37="Y","Not Eligible - SO Mapping Review","Eligible")))))) -> Eligible | AK37: =IF($AJ37="Eligible","Y","N") -> Y | AL37: =SUMIFS(SO_Mapping!$F:$F,SO_Mapping!$A:$A,$B37) -> 61098 | AM37: =IF(AND($N37<>"",$AL37=0),"Y",IF(ABS($O37-$AL37)>1,"Y","N")) -> N | AN37: =MAX(0,$K37-$AL37) -> 0 | AO37: =IF($AK37="Y","Cash eligible",IF($I37<>"Y","Excluded by control flag",IF($J37="","No expected close date",IF($X37="","No ship/invoice timing",IF($Y37="","No cash timing",IF($AM37="Y","SO mapping must be resolved","Review required")))))) -> Cash eligible | AP37: =IF($AK37="Y",TEXT($Y37,"yyyy-mm-dd"),"") -> 2026-03-27
A38: 42 | B38: DPS-0042 | C38: OUAI PET JAR - 250ml | D38: OUAI | E38: PRIMARY | F38: Q4 | G38: Jing Santos | H38: Open | I38: Y | K38: 200000 | L38: 0.25 | M38: 50000 | Q38: 200000 | R38: 0.0% | S38: Open | W38: OK | Z38: 0 | AC38: No SO Yet | AD38: 0 | AE38: 200000 | AF38: Low - Missing Timing | AG38: 2026-05-23 | AI38: =IF(OR($H38="Lost",$H38="Dead"),"Lost",IF($I38<>"Y","Excluded",IF($N38<>"","Converted/Partially Converted",IF($J38="","Watchlist","Active")))) -> Watchlist | AJ38: =IF($I38<>"Y","Not Eligible - Excluded",IF(OR($H38="Lost",$H38="Dead"),"Not Eligible - Lost",IF($J38="","Scenario Only - No Close Date",IF($X38="","Scenario Only - No Ship Date",IF($Y38="","Scenario Only - No Cash Date",IF($AM38="Y","Not Eligible - SO Mapping Review","Eligible")))))) -> Scenario Only - No Close Date | AK38: =IF($AJ38="Eligible","Y","N") -> N | AL38: =SUMIFS(SO_Mapping!$F:$F,SO_Mapping!$A:$A,$B38) -> 0 | AM38: =IF(AND($N38<>"",$AL38=0),"Y",IF(ABS($O38-$AL38)>1,"Y","N")) -> N | AN38: =MAX(0,$K38-$AL38) -> 200000 | AO38: =IF($AK38="Y","Cash eligible",IF($I38<>"Y","Excluded by control flag",IF($J38="","No expected close date",IF($X38="","No ship/invoice timing",IF($Y38="","No cash timing",IF($AM38="Y","SO mapping must be resolved","Review required")))))) -> No expected close date | AP38: =IF($AK38="Y",TEXT($Y38,"yyyy-mm-dd"),"")
A39: 43 | B39: DPS-0043 | C39: MOCKTAIL LINE | D39: BRAIN MD | E39: TURNKEY | F39: Q2 | G39: Jackie King | H39: Open | I39: Y | K39: 200000 | L39: 0.25 | M39: 50000 | Q39: 200000 | R39: 0.0% | S39: Open | W39: OK | Z39: 0 | AC39: No SO Yet | AD39: 0 | AE39: 200000 | AF39: Low - Missing Timing | AG39: 2026-05-23 | AI39: =IF(OR($H39="Lost",$H39="Dead"),"Lost",IF($I39<>"Y","Excluded",IF($N39<>"","Converted/Partially Converted",IF($J39="","Watchlist","Active")))) -> Watchlist | AJ39: =IF($I39<>"Y","Not Eligible - Excluded",IF(OR($H39="Lost",$H39="Dead"),"Not Eligible - Lost",IF($J39="","Scenario Only - No Close Date",IF($X39="","Scenario Only - No Ship Date",IF($Y39="","Scenario Only - No Cash Date",IF($AM39="Y","Not Eligible - SO Mapping Review","Eligible")))))) -> Scenario Only - No Close Date | AK39: =IF($AJ39="Eligible","Y","N") -> N | AL39: =SUMIFS(SO_Mapping!$F:$F,SO_Mapping!$A:$A,$B39) -> 0 | AM39: =IF(AND($N39<>"",$AL39=0),"Y",IF(ABS($O39-$AL39)>1,"Y","N")) -> N | AN39: =MAX(0,$K39-$AL39) -> 200000 | AO39: =IF($AK39="Y","Cash eligible",IF($I39<>"Y","Excluded by control flag",IF($J39="","No expected close date",IF($X39="","No ship/invoice timing",IF($Y39="","No cash timing",IF($AM39="Y","SO mapping must be resolved","Review required")))))) -> No expected close date | AP39: =IF($AK39="Y",TEXT($Y39,"yyyy-mm-dd"),"")
A40: 44 | B40: DPS-0044 | C40: Fiber Pills | D40: MISTR | E40: TURNKEY | F40: Q3 | G40: Jackie King | H40: Open | I40: Y | K40: 50000 | L40: 0.85 | M40: 42500 | Q40: 50000 | R40: 0.0% | S40: Open | W40: OK | Z40: 0 | AC40: No SO Yet | AD40: 0 | AE40: 50000 | AF40: Low - Missing Timing | AG40: 2026-05-23 | AI40: =IF(OR($H40="Lost",$H40="Dead"),"Lost",IF($I40<>"Y","Excluded",IF($N40<>"","Converted/Partially Converted",IF($J40="","Watchlist","Active")))) -> Watchlist | AJ40: =IF($I40<>"Y","Not Eligible - Excluded",IF(OR($H40="Lost",$H40="Dead"),"Not Eligible - Lost",IF($J40="","Scenario Only - No Close Date",IF($X40="","Scenario Only - No Ship Date",IF($Y40="","Scenario Only - No Cash Date",IF($AM40="Y","Not Eligible - SO Mapping Review","Eligible")))))) -> Scenario Only - No Close Date | AK40: =IF($AJ40="Eligible","Y","N") -> N | AL40: =SUMIFS(SO_Mapping!$F:$F,SO_Mapping!$A:$A,$B40) -> 0 | AM40: =IF(AND($N40<>"",$AL40=0),"Y",IF(ABS($O40-$AL40)>1,"Y","N")) -> N | AN40: =MAX(0,$K40-$AL40) -> 50000 | AO40: =IF($AK40="Y","Cash eligible",IF($I40<>"Y","Excluded by control flag",IF($J40="","No expected close date",IF($X40="","No ship/invoice timing",IF($Y40="","No cash timing",IF($AM40="Y","SO mapping must be resolved","Review required")))))) -> No expected close date | AP40: =IF($AK40="Y",TEXT($Y40,"yyyy-mm-dd"),"")
...

Sheet SO_Mapping
A1: Deal ID | B1: SO Number | C1: SO Status Text | D1: Source SO Amount | E1: Allocation % | F1: Allocated SO Amount | G1: Legacy Aggregate Approved SO Amount | H1: Allocation Review Required | I1: Notes
A2: DPS-0002 | B2: SO2599 | C2: Legacy listed | F2: =IF(OR($D2="",$E2=""),0,$D2*$E2) -> 0 | G2: 2672706 | H2: Y | I2: Multiple SOs listed; requires SO source amount/allocation before liquidity feed.
A3: DPS-0002 | B3: SO2597 | C3: Legacy listed | F3: =IF(OR($D3="",$E3=""),0,$D3*$E3) -> 0 | G3: 2672706 | H3: Y | I3: Multiple SOs listed; requires SO source amount/allocation before liquidity feed.
A4: DPS-0002 | B4: SO2598 | C4: Legacy listed | F4: =IF(OR($D4="",$E4=""),0,$D4*$E4) -> 0 | G4: 2672706 | H4: Y | I4: Multiple SOs listed; requires SO source amount/allocation before liquidity feed.
A5: DPS-0002 | B5: SO2608 | C5: Legacy listed | F5: =IF(OR($D5="",$E5=""),0,$D5*$E5) -> 0 | G5: 2672706 | H5: Y | I5: Multiple SOs listed; requires SO source amount/allocation before liquidity feed.
A6: DPS-0002 | B6: SO2609 | C6: Legacy listed | F6: =IF(OR($D6="",$E6=""),0,$D6*$E6) -> 0 | G6: 2672706 | H6: Y | I6: Multiple SOs listed; requires SO source amount/allocation before liquidity feed.
A7: DPS-0002 | B7: SO2610 | C7: Legacy listed | F7: =IF(OR($D7="",$E7=""),0,$D7*$E7) -> 0 | G7: 2672706 | H7: Y | I7: Multiple SOs listed; requires SO source amount/allocation before liquidity feed.
A8: DPS-0002 | B8: SO2611 | C8: Legacy listed | F8: =IF(OR($D8="",$E8=""),0,$D8*$E8) -> 0 | G8: 2672706 | H8: Y | I8: Multiple SOs listed; requires SO source amount/allocation before liquidity feed.
A9: DPS-0002 | B9: SO2612 | C9: Legacy listed | F9: =IF(OR($D9="",$E9=""),0,$D9*$E9) -> 0 | G9: 2672706 | H9: Y | I9: Multiple SOs listed; requires SO source amount/allocation before liquidity feed.
A10: DPS-0002 | B10: SO2613 | C10: Legacy listed | F10: =IF(OR($D10="",$E10=""),0,$D10*$E10) -> 0 | G10: 2672706 | H10: Y | I10: Multiple SOs listed; requires SO source amount/allocation before liquidity feed.
A11: DPS-0004 | B11: SO2601 | C11: Legacy listed | F11: =IF(OR($D11="",$E11=""),0,$D11*$E11) -> 0 | G11: 290080 | H11: Y | I11: Multiple SOs listed; requires SO source amount/allocation before liquidity feed.
A12: DPS-0004 | B12: SO2602 | C12: Legacy listed | F12: =IF(OR($D12="",$E12=""),0,$D12*$E12) -> 0 | G12: 290080 | H12: Y | I12: Multiple SOs listed; requires SO source amount/allocation before liquidity feed.
A13: DPS-0005 | B13: SO2563 | C13: Invoiced/Open per legacy note | F13: =IF(OR($D13="",$E13=""),0,$D13*$E13) -> 0 | G13: 1114750 | H13: Y | I13: Multiple SOs listed; requires SO source amount/allocation before liquidity feed.
... A25: DPS-0011 | B25: SO2551 | C25: Invoiced/Open per legacy note | F25: =IF(OR($D25="",$E25=""),0,$D25*$E25) -> 0 | G25: 65518 | H25: Y | I25: Multiple SOs listed; requires SO source amount/allocation before liquidity feed.
A26: DPS-0012 | B26: SO2554 | C26: Legacy listed | D26: 280000 | E26: 1 | F26: =IF(OR($D26="",$E26=""),0,$D26*$E26) -> 280000 | G26: 280000 | H26: N | I26: Single SO legacy amount used; verify against SO source.
A27: DPS-0013 | B27: SO2528 | C27: Legacy listed | F27: =IF(OR($D27="",$E27=""),0,$D27*$E27) -> 0 | G27: 380572 | H27: Y | I27: Multiple SOs listed; requires SO source amount/allocation before liquidity feed.
A28: DPS-0013 | B28: SO2492 | C28: Legacy listed | F28: =IF(OR($D28="",$E28=""),0,$D28*$E28) -> 0 | G28: 380572 | H28: Y | I28: Multiple SOs listed; requires SO source amount/allocation before liquidity feed.
A29: DPS-0013 | B29: SO2508 | C29: Legacy listed | F29: =IF(OR($D29="",$E29=""),0,$D29*$E29) -> 0 | G29: 380572 | H29: Y | I29: Multiple SOs listed; requires SO source amount/allocation before liquidity feed.
A30: DPS-0017 | B30: SO2605 | C30: Legacy listed | D30: 104760 | E30: 1 | F30: =IF(OR($D30="",$E30=""),0,$D30*$E30) -> 104760 | G30: 104760 | H30: N | I30: Single SO legacy amount used; verify against SO source.
